{
 "cells": [
  {
   "cell_type": "code",
   "execution_count": 5,
   "metadata": {},
   "outputs": [],
   "source": [
    "import pandas as pd\n",
    "import geopandas as gpd\n",
    "from shapely.geometry import Polygon, Point\n",
    "import requests\n",
    "import numpy as np\n",
    "import math\n",
    "from shapely.ops import nearest_points"
   ]
  },
  {
   "cell_type": "code",
   "execution_count": 7,
   "metadata": {},
   "outputs": [
    {
     "name": "stderr",
     "output_type": "stream",
     "text": [
      "ERROR:root:Internal Python error in the inspect module.\n",
      "Below is the traceback from this internal error.\n",
      "\n",
      "ERROR:root:Internal Python error in the inspect module.\n",
      "Below is the traceback from this internal error.\n",
      "\n",
      "ERROR:root:Internal Python error in the inspect module.\n",
      "Below is the traceback from this internal error.\n",
      "\n"
     ]
    },
    {
     "name": "stdout",
     "output_type": "stream",
     "text": [
      "Traceback (most recent call last):\n",
      "  File \"fiona/_shim.pyx\", line 74, in fiona._shim.gdal_open_vector\n",
      "  File \"fiona/_err.pyx\", line 291, in fiona._err.exc_wrap_pointer\n",
      "fiona._err.CPLE_OpenFailedError: ./output/stops_no_radius/stops_no_radius.shp: Operation not permitted\n",
      "\n",
      "During handling of the above exception, another exception occurred:\n",
      "\n",
      "Traceback (most recent call last):\n",
      "  File \"/Library/Frameworks/Python.framework/Versions/3.8/lib/python3.8/site-packages/IPython/core/interactiveshell.py\", line 3331, in run_code\n",
      "    exec(code_obj, self.user_global_ns, self.user_ns)\n",
      "  File \"<ipython-input-7-0f0e3d3e2264>\", line 1, in <module>\n",
      "    stops = gpd.read_file(\"./output/stops_no_radius/stops_no_radius.shp\")\n",
      "  File \"/Library/Frameworks/Python.framework/Versions/3.8/lib/python3.8/site-packages/geopandas/io/file.py\", line 96, in _read_file\n",
      "    with reader(path_or_bytes, **kwargs) as features:\n",
      "  File \"/Library/Frameworks/Python.framework/Versions/3.8/lib/python3.8/site-packages/fiona/env.py\", line 400, in wrapper\n",
      "    return f(*args, **kwargs)\n",
      "  File \"/Library/Frameworks/Python.framework/Versions/3.8/lib/python3.8/site-packages/fiona/__init__.py\", line 256, in open\n",
      "    c = Collection(path, mode, driver=driver, encoding=encoding,\n",
      "  File \"/Library/Frameworks/Python.framework/Versions/3.8/lib/python3.8/site-packages/fiona/collection.py\", line 164, in __init__\n",
      "    self.session.start(self, **kwargs)\n",
      "  File \"fiona/ogrext.pyx\", line 536, in fiona.ogrext.Session.start\n",
      "  File \"fiona/_shim.pyx\", line 81, in fiona._shim.gdal_open_vector\n",
      "fiona.errors.DriverError: ./output/stops_no_radius/stops_no_radius.shp: Operation not permitted\n",
      "\n",
      "During handling of the above exception, another exception occurred:\n",
      "\n",
      "Traceback (most recent call last):\n",
      "  File \"/Library/Frameworks/Python.framework/Versions/3.8/lib/python3.8/site-packages/IPython/core/interactiveshell.py\", line 2044, in showtraceback\n",
      "    stb = value._render_traceback_()\n",
      "AttributeError: 'DriverError' object has no attribute '_render_traceback_'\n",
      "\n",
      "During handling of the above exception, another exception occurred:\n",
      "\n",
      "Traceback (most recent call last):\n",
      "  File \"/Library/Frameworks/Python.framework/Versions/3.8/lib/python3.8/site-packages/IPython/core/ultratb.py\", line 1148, in get_records\n",
      "    return _fixed_getinnerframes(etb, number_of_lines_of_context, tb_offset)\n",
      "  File \"/Library/Frameworks/Python.framework/Versions/3.8/lib/python3.8/site-packages/IPython/core/ultratb.py\", line 316, in wrapped\n",
      "    return f(*args, **kwargs)\n",
      "  File \"/Library/Frameworks/Python.framework/Versions/3.8/lib/python3.8/site-packages/IPython/core/ultratb.py\", line 350, in _fixed_getinnerframes\n",
      "    records = fix_frame_records_filenames(inspect.getinnerframes(etb, context))\n",
      "  File \"/Library/Frameworks/Python.framework/Versions/3.8/lib/python3.8/inspect.py\", line 1503, in getinnerframes\n",
      "    frameinfo = (tb.tb_frame,) + getframeinfo(tb, context)\n",
      "  File \"/Library/Frameworks/Python.framework/Versions/3.8/lib/python3.8/inspect.py\", line 1461, in getframeinfo\n",
      "    filename = getsourcefile(frame) or getfile(frame)\n",
      "  File \"/Library/Frameworks/Python.framework/Versions/3.8/lib/python3.8/inspect.py\", line 708, in getsourcefile\n",
      "    if getattr(getmodule(object, filename), '__loader__', None) is not None:\n",
      "  File \"/Library/Frameworks/Python.framework/Versions/3.8/lib/python3.8/inspect.py\", line 737, in getmodule\n",
      "    file = getabsfile(object, _filename)\n",
      "  File \"/Library/Frameworks/Python.framework/Versions/3.8/lib/python3.8/inspect.py\", line 721, in getabsfile\n",
      "    return os.path.normcase(os.path.abspath(_filename))\n",
      "  File \"/Library/Frameworks/Python.framework/Versions/3.8/lib/python3.8/posixpath.py\", line 379, in abspath\n",
      "    cwd = os.getcwd()\n",
      "PermissionError: [Errno 1] Operation not permitted\n",
      "Traceback (most recent call last):\n",
      "  File \"fiona/_shim.pyx\", line 74, in fiona._shim.gdal_open_vector\n",
      "  File \"fiona/_err.pyx\", line 291, in fiona._err.exc_wrap_pointer\n",
      "fiona._err.CPLE_OpenFailedError: ./output/stops_no_radius/stops_no_radius.shp: Operation not permitted\n",
      "\n",
      "During handling of the above exception, another exception occurred:\n",
      "\n",
      "Traceback (most recent call last):\n",
      "  File \"/Library/Frameworks/Python.framework/Versions/3.8/lib/python3.8/site-packages/IPython/core/interactiveshell.py\", line 3331, in run_code\n",
      "    exec(code_obj, self.user_global_ns, self.user_ns)\n",
      "  File \"<ipython-input-7-0f0e3d3e2264>\", line 1, in <module>\n",
      "    stops = gpd.read_file(\"./output/stops_no_radius/stops_no_radius.shp\")\n",
      "  File \"/Library/Frameworks/Python.framework/Versions/3.8/lib/python3.8/site-packages/geopandas/io/file.py\", line 96, in _read_file\n",
      "    with reader(path_or_bytes, **kwargs) as features:\n",
      "  File \"/Library/Frameworks/Python.framework/Versions/3.8/lib/python3.8/site-packages/fiona/env.py\", line 400, in wrapper\n",
      "    return f(*args, **kwargs)\n",
      "  File \"/Library/Frameworks/Python.framework/Versions/3.8/lib/python3.8/site-packages/fiona/__init__.py\", line 256, in open\n",
      "    c = Collection(path, mode, driver=driver, encoding=encoding,\n",
      "  File \"/Library/Frameworks/Python.framework/Versions/3.8/lib/python3.8/site-packages/fiona/collection.py\", line 164, in __init__\n",
      "    self.session.start(self, **kwargs)\n",
      "  File \"fiona/ogrext.pyx\", line 536, in fiona.ogrext.Session.start\n",
      "  File \"fiona/_shim.pyx\", line 81, in fiona._shim.gdal_open_vector\n",
      "fiona.errors.DriverError: ./output/stops_no_radius/stops_no_radius.shp: Operation not permitted\n",
      "\n",
      "During handling of the above exception, another exception occurred:\n",
      "\n",
      "Traceback (most recent call last):\n",
      "  File \"/Library/Frameworks/Python.framework/Versions/3.8/lib/python3.8/site-packages/IPython/core/interactiveshell.py\", line 2044, in showtraceback\n",
      "    stb = value._render_traceback_()\n",
      "AttributeError: 'DriverError' object has no attribute '_render_traceback_'\n",
      "\n",
      "During handling of the above exception, another exception occurred:\n",
      "\n",
      "Traceback (most recent call last):\n",
      "  File \"/Library/Frameworks/Python.framework/Versions/3.8/lib/python3.8/site-packages/IPython/core/interactiveshell.py\", line 3254, in run_ast_nodes\n",
      "    if (await self.run_code(code, result,  async_=asy)):\n",
      "  File \"/Library/Frameworks/Python.framework/Versions/3.8/lib/python3.8/site-packages/IPython/core/interactiveshell.py\", line 3348, in run_code\n",
      "    self.showtraceback(running_compiled_code=True)\n",
      "  File \"/Library/Frameworks/Python.framework/Versions/3.8/lib/python3.8/site-packages/IPython/core/interactiveshell.py\", line 2046, in showtraceback\n",
      "    stb = self.InteractiveTB.structured_traceback(etype,\n",
      "  File \"/Library/Frameworks/Python.framework/Versions/3.8/lib/python3.8/site-packages/IPython/core/ultratb.py\", line 1414, in structured_traceback\n",
      "    return FormattedTB.structured_traceback(\n",
      "  File \"/Library/Frameworks/Python.framework/Versions/3.8/lib/python3.8/site-packages/IPython/core/ultratb.py\", line 1314, in structured_traceback\n",
      "    return VerboseTB.structured_traceback(\n",
      "  File \"/Library/Frameworks/Python.framework/Versions/3.8/lib/python3.8/site-packages/IPython/core/ultratb.py\", line 1183, in structured_traceback\n",
      "    formatted_exceptions += self.prepare_chained_exception_message(evalue.__cause__)\n",
      "TypeError: can only concatenate str (not \"list\") to str\n",
      "\n",
      "During handling of the above exception, another exception occurred:\n",
      "\n",
      "Traceback (most recent call last):\n",
      "  File \"/Library/Frameworks/Python.framework/Versions/3.8/lib/python3.8/site-packages/IPython/core/interactiveshell.py\", line 2044, in showtraceback\n",
      "    stb = value._render_traceback_()\n",
      "AttributeError: 'TypeError' object has no attribute '_render_traceback_'\n",
      "\n",
      "During handling of the above exception, another exception occurred:\n",
      "\n",
      "Traceback (most recent call last):\n",
      "  File \"/Library/Frameworks/Python.framework/Versions/3.8/lib/python3.8/site-packages/IPython/core/ultratb.py\", line 1148, in get_records\n",
      "    return _fixed_getinnerframes(etb, number_of_lines_of_context, tb_offset)\n",
      "  File \"/Library/Frameworks/Python.framework/Versions/3.8/lib/python3.8/site-packages/IPython/core/ultratb.py\", line 316, in wrapped\n",
      "    return f(*args, **kwargs)\n",
      "  File \"/Library/Frameworks/Python.framework/Versions/3.8/lib/python3.8/site-packages/IPython/core/ultratb.py\", line 350, in _fixed_getinnerframes\n",
      "    records = fix_frame_records_filenames(inspect.getinnerframes(etb, context))\n",
      "  File \"/Library/Frameworks/Python.framework/Versions/3.8/lib/python3.8/inspect.py\", line 1503, in getinnerframes\n",
      "    frameinfo = (tb.tb_frame,) + getframeinfo(tb, context)\n",
      "  File \"/Library/Frameworks/Python.framework/Versions/3.8/lib/python3.8/inspect.py\", line 1461, in getframeinfo\n",
      "    filename = getsourcefile(frame) or getfile(frame)\n",
      "  File \"/Library/Frameworks/Python.framework/Versions/3.8/lib/python3.8/inspect.py\", line 708, in getsourcefile\n",
      "    if getattr(getmodule(object, filename), '__loader__', None) is not None:\n",
      "  File \"/Library/Frameworks/Python.framework/Versions/3.8/lib/python3.8/inspect.py\", line 737, in getmodule\n",
      "    file = getabsfile(object, _filename)\n",
      "  File \"/Library/Frameworks/Python.framework/Versions/3.8/lib/python3.8/inspect.py\", line 721, in getabsfile\n",
      "    return os.path.normcase(os.path.abspath(_filename))\n",
      "  File \"/Library/Frameworks/Python.framework/Versions/3.8/lib/python3.8/posixpath.py\", line 379, in abspath\n",
      "    cwd = os.getcwd()\n",
      "PermissionError: [Errno 1] Operation not permitted\n",
      "Traceback (most recent call last):\n",
      "  File \"fiona/_shim.pyx\", line 74, in fiona._shim.gdal_open_vector\n",
      "  File \"fiona/_err.pyx\", line 291, in fiona._err.exc_wrap_pointer\n",
      "fiona._err.CPLE_OpenFailedError: ./output/stops_no_radius/stops_no_radius.shp: Operation not permitted\n",
      "\n",
      "During handling of the above exception, another exception occurred:\n",
      "\n",
      "Traceback (most recent call last):\n",
      "  File \"/Library/Frameworks/Python.framework/Versions/3.8/lib/python3.8/site-packages/IPython/core/interactiveshell.py\", line 3331, in run_code\n",
      "    exec(code_obj, self.user_global_ns, self.user_ns)\n",
      "  File \"<ipython-input-7-0f0e3d3e2264>\", line 1, in <module>\n",
      "    stops = gpd.read_file(\"./output/stops_no_radius/stops_no_radius.shp\")\n",
      "  File \"/Library/Frameworks/Python.framework/Versions/3.8/lib/python3.8/site-packages/geopandas/io/file.py\", line 96, in _read_file\n",
      "    with reader(path_or_bytes, **kwargs) as features:\n",
      "  File \"/Library/Frameworks/Python.framework/Versions/3.8/lib/python3.8/site-packages/fiona/env.py\", line 400, in wrapper\n",
      "    return f(*args, **kwargs)\n",
      "  File \"/Library/Frameworks/Python.framework/Versions/3.8/lib/python3.8/site-packages/fiona/__init__.py\", line 256, in open\n",
      "    c = Collection(path, mode, driver=driver, encoding=encoding,\n",
      "  File \"/Library/Frameworks/Python.framework/Versions/3.8/lib/python3.8/site-packages/fiona/collection.py\", line 164, in __init__\n",
      "    self.session.start(self, **kwargs)\n",
      "  File \"fiona/ogrext.pyx\", line 536, in fiona.ogrext.Session.start\n",
      "  File \"fiona/_shim.pyx\", line 81, in fiona._shim.gdal_open_vector\n",
      "fiona.errors.DriverError: ./output/stops_no_radius/stops_no_radius.shp: Operation not permitted\n",
      "\n",
      "During handling of the above exception, another exception occurred:\n",
      "\n",
      "Traceback (most recent call last):\n",
      "  File \"/Library/Frameworks/Python.framework/Versions/3.8/lib/python3.8/site-packages/IPython/core/interactiveshell.py\", line 2044, in showtraceback\n",
      "    stb = value._render_traceback_()\n",
      "AttributeError: 'DriverError' object has no attribute '_render_traceback_'\n",
      "\n",
      "During handling of the above exception, another exception occurred:\n",
      "\n",
      "Traceback (most recent call last):\n",
      "  File \"/Library/Frameworks/Python.framework/Versions/3.8/lib/python3.8/site-packages/IPython/core/interactiveshell.py\", line 3254, in run_ast_nodes\n",
      "    if (await self.run_code(code, result,  async_=asy)):\n",
      "  File \"/Library/Frameworks/Python.framework/Versions/3.8/lib/python3.8/site-packages/IPython/core/interactiveshell.py\", line 3348, in run_code\n",
      "    self.showtraceback(running_compiled_code=True)\n",
      "  File \"/Library/Frameworks/Python.framework/Versions/3.8/lib/python3.8/site-packages/IPython/core/interactiveshell.py\", line 2046, in showtraceback\n",
      "    stb = self.InteractiveTB.structured_traceback(etype,\n",
      "  File \"/Library/Frameworks/Python.framework/Versions/3.8/lib/python3.8/site-packages/IPython/core/ultratb.py\", line 1414, in structured_traceback\n",
      "    return FormattedTB.structured_traceback(\n",
      "  File \"/Library/Frameworks/Python.framework/Versions/3.8/lib/python3.8/site-packages/IPython/core/ultratb.py\", line 1314, in structured_traceback\n",
      "    return VerboseTB.structured_traceback(\n",
      "  File \"/Library/Frameworks/Python.framework/Versions/3.8/lib/python3.8/site-packages/IPython/core/ultratb.py\", line 1183, in structured_traceback\n",
      "    formatted_exceptions += self.prepare_chained_exception_message(evalue.__cause__)\n",
      "TypeError: can only concatenate str (not \"list\") to str\n",
      "\n",
      "During handling of the above exception, another exception occurred:\n",
      "\n",
      "Traceback (most recent call last):\n",
      "  File \"/Library/Frameworks/Python.framework/Versions/3.8/lib/python3.8/site-packages/IPython/core/interactiveshell.py\", line 2044, in showtraceback\n",
      "    stb = value._render_traceback_()\n",
      "AttributeError: 'TypeError' object has no attribute '_render_traceback_'\n",
      "\n",
      "During handling of the above exception, another exception occurred:\n",
      "\n",
      "Traceback (most recent call last):\n",
      "  File \"/Library/Frameworks/Python.framework/Versions/3.8/lib/python3.8/site-packages/IPython/core/ultratb.py\", line 1148, in get_records\n",
      "    return _fixed_getinnerframes(etb, number_of_lines_of_context, tb_offset)\n",
      "  File \"/Library/Frameworks/Python.framework/Versions/3.8/lib/python3.8/site-packages/IPython/core/ultratb.py\", line 316, in wrapped\n",
      "    return f(*args, **kwargs)\n",
      "  File \"/Library/Frameworks/Python.framework/Versions/3.8/lib/python3.8/site-packages/IPython/core/ultratb.py\", line 350, in _fixed_getinnerframes\n",
      "    records = fix_frame_records_filenames(inspect.getinnerframes(etb, context))\n",
      "  File \"/Library/Frameworks/Python.framework/Versions/3.8/lib/python3.8/inspect.py\", line 1503, in getinnerframes\n",
      "    frameinfo = (tb.tb_frame,) + getframeinfo(tb, context)\n",
      "  File \"/Library/Frameworks/Python.framework/Versions/3.8/lib/python3.8/inspect.py\", line 1461, in getframeinfo\n",
      "    filename = getsourcefile(frame) or getfile(frame)\n",
      "  File \"/Library/Frameworks/Python.framework/Versions/3.8/lib/python3.8/inspect.py\", line 708, in getsourcefile\n",
      "    if getattr(getmodule(object, filename), '__loader__', None) is not None:\n",
      "  File \"/Library/Frameworks/Python.framework/Versions/3.8/lib/python3.8/inspect.py\", line 737, in getmodule\n",
      "    file = getabsfile(object, _filename)\n",
      "  File \"/Library/Frameworks/Python.framework/Versions/3.8/lib/python3.8/inspect.py\", line 721, in getabsfile\n",
      "    return os.path.normcase(os.path.abspath(_filename))\n",
      "  File \"/Library/Frameworks/Python.framework/Versions/3.8/lib/python3.8/posixpath.py\", line 379, in abspath\n",
      "    cwd = os.getcwd()\n",
      "PermissionError: [Errno 1] Operation not permitted\n"
     ]
    },
    {
     "ename": "TypeError",
     "evalue": "can only concatenate str (not \"list\") to str",
     "output_type": "error",
     "traceback": [
      "\u001b[0;31m---------------------------------------------------------------------------\u001b[0m",
      "\nDuring handling of the above exception, another exception occurred:\n",
      "\nDuring handling of the above exception, another exception occurred:\n",
      "\u001b[0;31mAttributeError\u001b[0m                            Traceback (most recent call last)",
      "\u001b[0;32m/Library/Frameworks/Python.framework/Versions/3.8/lib/python3.8/site-packages/IPython/core/interactiveshell.py\u001b[0m in \u001b[0;36mshowtraceback\u001b[0;34m(self, exc_tuple, filename, tb_offset, exception_only, running_compiled_code)\u001b[0m\n\u001b[1;32m   2043\u001b[0m                         \u001b[0;31m# in the engines. This should return a list of strings.\u001b[0m\u001b[0;34m\u001b[0m\u001b[0;34m\u001b[0m\u001b[0;34m\u001b[0m\u001b[0m\n\u001b[0;32m-> 2044\u001b[0;31m                         \u001b[0mstb\u001b[0m \u001b[0;34m=\u001b[0m \u001b[0mvalue\u001b[0m\u001b[0;34m.\u001b[0m\u001b[0m_render_traceback_\u001b[0m\u001b[0;34m(\u001b[0m\u001b[0;34m)\u001b[0m\u001b[0;34m\u001b[0m\u001b[0;34m\u001b[0m\u001b[0m\n\u001b[0m\u001b[1;32m   2045\u001b[0m                     \u001b[0;32mexcept\u001b[0m \u001b[0mException\u001b[0m\u001b[0;34m:\u001b[0m\u001b[0;34m\u001b[0m\u001b[0;34m\u001b[0m\u001b[0m\n",
      "\u001b[0;31mAttributeError\u001b[0m: 'DriverError' object has no attribute '_render_traceback_'",
      "\nDuring handling of the above exception, another exception occurred:\n",
      "\u001b[0;31mTypeError\u001b[0m                                 Traceback (most recent call last)",
      "\u001b[0;32m/Library/Frameworks/Python.framework/Versions/3.8/lib/python3.8/site-packages/IPython/core/interactiveshell.py\u001b[0m in \u001b[0;36mrun_code\u001b[0;34m(self, code_obj, result, async_)\u001b[0m\n\u001b[1;32m   3346\u001b[0m             \u001b[0;32mif\u001b[0m \u001b[0mresult\u001b[0m \u001b[0;32mis\u001b[0m \u001b[0;32mnot\u001b[0m \u001b[0;32mNone\u001b[0m\u001b[0;34m:\u001b[0m\u001b[0;34m\u001b[0m\u001b[0;34m\u001b[0m\u001b[0m\n\u001b[1;32m   3347\u001b[0m                 \u001b[0mresult\u001b[0m\u001b[0;34m.\u001b[0m\u001b[0merror_in_exec\u001b[0m \u001b[0;34m=\u001b[0m \u001b[0msys\u001b[0m\u001b[0;34m.\u001b[0m\u001b[0mexc_info\u001b[0m\u001b[0;34m(\u001b[0m\u001b[0;34m)\u001b[0m\u001b[0;34m[\u001b[0m\u001b[0;36m1\u001b[0m\u001b[0;34m]\u001b[0m\u001b[0;34m\u001b[0m\u001b[0;34m\u001b[0m\u001b[0m\n\u001b[0;32m-> 3348\u001b[0;31m             \u001b[0mself\u001b[0m\u001b[0;34m.\u001b[0m\u001b[0mshowtraceback\u001b[0m\u001b[0;34m(\u001b[0m\u001b[0mrunning_compiled_code\u001b[0m\u001b[0;34m=\u001b[0m\u001b[0;32mTrue\u001b[0m\u001b[0;34m)\u001b[0m\u001b[0;34m\u001b[0m\u001b[0;34m\u001b[0m\u001b[0m\n\u001b[0m\u001b[1;32m   3349\u001b[0m         \u001b[0;32melse\u001b[0m\u001b[0;34m:\u001b[0m\u001b[0;34m\u001b[0m\u001b[0;34m\u001b[0m\u001b[0m\n\u001b[1;32m   3350\u001b[0m             \u001b[0moutflag\u001b[0m \u001b[0;34m=\u001b[0m \u001b[0;32mFalse\u001b[0m\u001b[0;34m\u001b[0m\u001b[0;34m\u001b[0m\u001b[0m\n",
      "\u001b[0;32m/Library/Frameworks/Python.framework/Versions/3.8/lib/python3.8/site-packages/IPython/core/interactiveshell.py\u001b[0m in \u001b[0;36mshowtraceback\u001b[0;34m(self, exc_tuple, filename, tb_offset, exception_only, running_compiled_code)\u001b[0m\n\u001b[1;32m   2044\u001b[0m                         \u001b[0mstb\u001b[0m \u001b[0;34m=\u001b[0m \u001b[0mvalue\u001b[0m\u001b[0;34m.\u001b[0m\u001b[0m_render_traceback_\u001b[0m\u001b[0;34m(\u001b[0m\u001b[0;34m)\u001b[0m\u001b[0;34m\u001b[0m\u001b[0;34m\u001b[0m\u001b[0m\n\u001b[1;32m   2045\u001b[0m                     \u001b[0;32mexcept\u001b[0m \u001b[0mException\u001b[0m\u001b[0;34m:\u001b[0m\u001b[0;34m\u001b[0m\u001b[0;34m\u001b[0m\u001b[0m\n\u001b[0;32m-> 2046\u001b[0;31m                         stb = self.InteractiveTB.structured_traceback(etype,\n\u001b[0m\u001b[1;32m   2047\u001b[0m                                             value, tb, tb_offset=tb_offset)\n\u001b[1;32m   2048\u001b[0m \u001b[0;34m\u001b[0m\u001b[0m\n",
      "\u001b[0;32m/Library/Frameworks/Python.framework/Versions/3.8/lib/python3.8/site-packages/IPython/core/ultratb.py\u001b[0m in \u001b[0;36mstructured_traceback\u001b[0;34m(self, etype, value, tb, tb_offset, number_of_lines_of_context)\u001b[0m\n\u001b[1;32m   1412\u001b[0m         \u001b[0;32melse\u001b[0m\u001b[0;34m:\u001b[0m\u001b[0;34m\u001b[0m\u001b[0;34m\u001b[0m\u001b[0m\n\u001b[1;32m   1413\u001b[0m             \u001b[0mself\u001b[0m\u001b[0;34m.\u001b[0m\u001b[0mtb\u001b[0m \u001b[0;34m=\u001b[0m \u001b[0mtb\u001b[0m\u001b[0;34m\u001b[0m\u001b[0;34m\u001b[0m\u001b[0m\n\u001b[0;32m-> 1414\u001b[0;31m         return FormattedTB.structured_traceback(\n\u001b[0m\u001b[1;32m   1415\u001b[0m             self, etype, value, tb, tb_offset, number_of_lines_of_context)\n\u001b[1;32m   1416\u001b[0m \u001b[0;34m\u001b[0m\u001b[0m\n",
      "\u001b[0;32m/Library/Frameworks/Python.framework/Versions/3.8/lib/python3.8/site-packages/IPython/core/ultratb.py\u001b[0m in \u001b[0;36mstructured_traceback\u001b[0;34m(self, etype, value, tb, tb_offset, number_of_lines_of_context)\u001b[0m\n\u001b[1;32m   1312\u001b[0m         \u001b[0;32mif\u001b[0m \u001b[0mmode\u001b[0m \u001b[0;32min\u001b[0m \u001b[0mself\u001b[0m\u001b[0;34m.\u001b[0m\u001b[0mverbose_modes\u001b[0m\u001b[0;34m:\u001b[0m\u001b[0;34m\u001b[0m\u001b[0;34m\u001b[0m\u001b[0m\n\u001b[1;32m   1313\u001b[0m             \u001b[0;31m# Verbose modes need a full traceback\u001b[0m\u001b[0;34m\u001b[0m\u001b[0;34m\u001b[0m\u001b[0;34m\u001b[0m\u001b[0m\n\u001b[0;32m-> 1314\u001b[0;31m             return VerboseTB.structured_traceback(\n\u001b[0m\u001b[1;32m   1315\u001b[0m                 \u001b[0mself\u001b[0m\u001b[0;34m,\u001b[0m \u001b[0metype\u001b[0m\u001b[0;34m,\u001b[0m \u001b[0mvalue\u001b[0m\u001b[0;34m,\u001b[0m \u001b[0mtb\u001b[0m\u001b[0;34m,\u001b[0m \u001b[0mtb_offset\u001b[0m\u001b[0;34m,\u001b[0m \u001b[0mnumber_of_lines_of_context\u001b[0m\u001b[0;34m\u001b[0m\u001b[0;34m\u001b[0m\u001b[0m\n\u001b[1;32m   1316\u001b[0m             )\n",
      "\u001b[0;32m/Library/Frameworks/Python.framework/Versions/3.8/lib/python3.8/site-packages/IPython/core/ultratb.py\u001b[0m in \u001b[0;36mstructured_traceback\u001b[0;34m(self, etype, evalue, etb, tb_offset, number_of_lines_of_context)\u001b[0m\n\u001b[1;32m   1181\u001b[0m         \u001b[0mexception\u001b[0m \u001b[0;34m=\u001b[0m \u001b[0mself\u001b[0m\u001b[0;34m.\u001b[0m\u001b[0mget_parts_of_chained_exception\u001b[0m\u001b[0;34m(\u001b[0m\u001b[0mevalue\u001b[0m\u001b[0;34m)\u001b[0m\u001b[0;34m\u001b[0m\u001b[0;34m\u001b[0m\u001b[0m\n\u001b[1;32m   1182\u001b[0m         \u001b[0;32mif\u001b[0m \u001b[0mexception\u001b[0m\u001b[0;34m:\u001b[0m\u001b[0;34m\u001b[0m\u001b[0;34m\u001b[0m\u001b[0m\n\u001b[0;32m-> 1183\u001b[0;31m             \u001b[0mformatted_exceptions\u001b[0m \u001b[0;34m+=\u001b[0m \u001b[0mself\u001b[0m\u001b[0;34m.\u001b[0m\u001b[0mprepare_chained_exception_message\u001b[0m\u001b[0;34m(\u001b[0m\u001b[0mevalue\u001b[0m\u001b[0;34m.\u001b[0m\u001b[0m__cause__\u001b[0m\u001b[0;34m)\u001b[0m\u001b[0;34m\u001b[0m\u001b[0;34m\u001b[0m\u001b[0m\n\u001b[0m\u001b[1;32m   1184\u001b[0m             \u001b[0metype\u001b[0m\u001b[0;34m,\u001b[0m \u001b[0mevalue\u001b[0m\u001b[0;34m,\u001b[0m \u001b[0metb\u001b[0m \u001b[0;34m=\u001b[0m \u001b[0mexception\u001b[0m\u001b[0;34m\u001b[0m\u001b[0;34m\u001b[0m\u001b[0m\n\u001b[1;32m   1185\u001b[0m         \u001b[0;32melse\u001b[0m\u001b[0;34m:\u001b[0m\u001b[0;34m\u001b[0m\u001b[0;34m\u001b[0m\u001b[0m\n",
      "\u001b[0;31mTypeError\u001b[0m: can only concatenate str (not \"list\") to str"
     ]
    }
   ],
   "source": [
    "stops = gpd.read_file(\"./output/stops_no_radius/stops_no_radius.shp\")"
   ]
  },
  {
   "cell_type": "code",
   "execution_count": null,
   "metadata": {},
   "outputs": [],
   "source": [
    "stops"
   ]
  },
  {
   "cell_type": "code",
   "execution_count": null,
   "metadata": {},
   "outputs": [],
   "source": []
  }
 ],
 "metadata": {
  "kernelspec": {
   "display_name": "Python 3",
   "language": "python",
   "name": "python3"
  },
  "language_info": {
   "codemirror_mode": {
    "name": "ipython",
    "version": 3
   },
   "file_extension": ".py",
   "mimetype": "text/x-python",
   "name": "python",
   "nbconvert_exporter": "python",
   "pygments_lexer": "ipython3",
   "version": "3.8.1"
  }
 },
 "nbformat": 4,
 "nbformat_minor": 4
}
